2022-02-26 17:43:11,259 - base_log.py[line:31] - ERROR: 执行用例1的时候报错:
2022-02-26 17:43:13,964 - base_log.py[line:31] - ERROR: 执行用例2的时候报错:
2022-02-26 17:43:14,997 - base_log.py[line:31] - ERROR: 执行用例3的时候报错:
2022-02-26 17:43:16,326 - base_log.py[line:31] - ERROR: 执行用例4的时候报错:
2022-02-26 17:43:16,713 - base_log.py[line:31] - ERROR: 执行用例5的时候报错:
2022-02-26 17:43:17,722 - base_log.py[line:31] - ERROR: 执行用例6的时候报错:
2022-02-26 17:43:18,159 - base_log.py[line:31] - ERROR: 执行用例7的时候报错:
2022-02-26 17:43:18,505 - base_log.py[line:31] - ERROR: 执行用例8的时候报错:
2022-02-26 17:43:19,438 - base_log.py[line:31] - ERROR: 执行用例9的时候报错:
2022-02-26 17:43:19,884 - base_log.py[line:31] - ERROR: 执行用例10的时候报错:
2022-02-26 17:43:20,850 - base_log.py[line:31] - ERROR: 执行用例11的时候报错: :: 200 != 500
